Workbook

Sheet Raw_Backup
A1: OrderID | B1: Date | C1: CustomerID | D1: Product | E1: Quantity | F1: UnitPrice | G1: ShippingAddress | H1: PaymentMethod | I1: OrderStatus | J1: TrackingNumber | K1: ItemsInCart | L1: CouponCode | M1: ReferralSource | N1: TotalPrice
A2: ORD200000 | B2: 44930 | C2: C72649 | D2: Monitor | E2: 5 | F2: 570.62 | G2: 928 Main St | H2: Debit Card | I2: Shipped | J2: TRK37947903 | K2: 7 | L2: SAVE10 | M2: Instagram | N2: 2853.1
A3: ORD200001 | B3: 45527 | C3: C75739 | D3: Phone | E3: 2 | F3: 151.35 | G3: 823 Main St | H3: Online | I3: Shipped | J3: TRK91186779 | K3: 3 | L3: SAVE10 | M3: Referral | N3: 302.7
A4: ORD200002 | B4: 45349 | C4: C81728 | D4: Tablet | E4: 5 | F4: 550.68 | G4: 512 Main St | H4: Credit Card | I4: Cancelled | J4: TRK42903982 | K4: 8 | L4: FREESHIP | M4: Email | N4: 2753.4
A5: ORD200003 | B5: 45214 | C5: C33540 | D5: Chair | E5: 1 | F5: 273.19 | G5: 275 Main St | H5: Debit Card | I5: Returned | J5: TRK62788070 | K5: 5 | L5: SAVE10 | M5: Facebook | N5: 273.19
A6: ORD200004 | B6: 45785 | C6: C81840 | D6: Printer | E6: 4 | F6: 626.01 | G6: 668 Main St | H6: Online | I6: Delivered | J6: TRK29241424 | K6: 8 | L6: SAVE10 | M6: Email | N6: 2504.04
A7: ORD200005 | B7: 45222 | C7: C37249 | D7: Phone | E7: 2 | F7: 245.86 | G7: 934 Main St | H7: Credit Card | I7: Shipped | J7: TRK72976927 | K7: 4 | L7: SAVE10 | M7: Instagram | N7: 491.72
A8: ORD200006 | B8: 45825 | C8: C83492 | D8: Laptop | E8: 1 | F8: 664.42 | G8: 986 Main St | H8: Gift Card | I8: Returned | J8: TRK96417362 | K8: 6 | L8: SAVE10 | M8: Facebook | N8: 664.42
A9: ORD200007 | B9: 45058 | C9: C41460 | D9: Monitor | E9: 5 | F9: 149.55 | G9: 706 Main St | H9: Cash | I9: Shipped | J9: TRK78809193 | K9: 9 | L9: FREESHIP | M9: Facebook | N9: 747.75
A10: ORD200008 | B10: 45749 | C10: C26817 | D10: Phone | E10: 2 | F10: 134.28 | G10: 904 Main St | H10: Gift Card | I10: Cancelled | J10: TRK61042692 | K10: 2 | M10: Email | N10: 268.56
A11: ORD200009 | B11: 45251 | C11: C31946 | D11: Desk | E11: 4 | F11: 509.38 | G11: 102 Main St | H11: Credit Card | I11: Shipped | J11: TRK33478363 | K11: 6 | L11: SAVE10 | M11: Google | N11: 2037.52
A12: ORD200010 | B12: 45289 | C12: C43443 | D12: Tablet | E12: 5 | F12: 625.97 | G12: 333 Main St | H12: Credit Card | I12: Returned | J12: TRK98859248 | K12: 9 | L12: WINTER15 | M12: Instagram | N12: 3129.85
A13: ORD200011 | B13: 45339 | C13: C93861 | D13: Monitor | E13: 3 | F13: 49.14 | G13: 831 Main St | H13: Online | I13: Returned | J13: TRK48234646 | K13: 7 | L13: SAVE10 | M13: Email | N13: 147.42
A14: ORD200012 | B14: 45580 | C14: C38785 | D14: Monitor | E14: 2 | F14: 180.5 | G14: 179 Main St | H14: Debit Card | I14: Pending | J14: TRK20419991 | K14: 6 | L14: FREESHIP | M14: Referral | N14: 361
A15: ORD200013 | B15: 45168 | C15: C88348 | D15: Laptop | E15: 3 | F15: 201.49 | G15: 903 Main St | H15: Credit Card | I15: Returned | J15: TRK81913874 | K15: 4 | L15: FREESHIP | M15: Facebook | N15: 604.47
A16: ORD200014 | B16: 45012 | C16: C98474 | D16: Tablet | E16: 2 | F16: 393.33 | G16: 980 Main St | H16: Debit Card | I16: Pending | J16: TRK79186539 | K16: 3 | L16: SAVE10 | M16: Instagram | N16: 786.66
A17: ORD200015 | B17: 45124 | C17: C39416 | D17: Printer | E17: 1 | F17: 473.96 | G17: 942 Main St | H17: Cash | I17: Delivered | J17: TRK54930938 | K17: 3 | M17: Google | N17: 473.96
A18: ORD200016 | B18: 44950 | C18: C28976 | D18: Printer | E18: 2 | F18: 533.81 | G18: 914 Main St | H18: Credit Card | I18: Pending | J18: TRK13194259 | K18: 3 | L18: FREESHIP | M18: Email | N18: 1067.62
A19: ORD200017 | B19: 45353 | C19: C60672 | D19: Tablet | E19: 1 | F19: 423.4 | G19: 382 Main St | H19: Debit Card | I19: Shipped | J19: TRK11972116 | K19: 3 | M19: Referral | N19: 423.4
A20: ORD200018 | B20: 45742 | C20: C84329 | D20: Desk | E20: 1 | F20: 431.44 | G20: 891 Main St | H20: Gift Card | I20: Pending | J20: TRK65191045 | K20: 3 | L20: SAVE10 | M20: Facebook | N20: 431.44
A21: ORD200019 | B21: 44949 | C21: C14552 | D21: Monitor | E21: 5 | F21: 224 | G21: 273 Main St | H21: Cash | I21: Returned | J21: TRK59101365 | K21: 9 | L21: SAVE10 | M21: Google | N21: 1120
A22: ORD200020 | B22: 45054 | C22: C54829 | D22: Chair | E22: 5 | F22: 62.51 | G22: 587 Main St | H22: Cash | I22: Pending | J22: TRK16718651 | K22: 9 | L22: WINTER15 | M22: Instagram | N22: 312.55
A23: ORD200021 | B23: 45613 | C23: C99023 | D23: Monitor | E23: 4 | F23: 342.95 | G23: 569 Main St | H23: Cash | I23: Delivered | J23: TRK52646983 | K23: 6 | M23: Google | N23: 1371.8
A24: ORD200022 | B24: 44955 | C24: C34416 | D24: Monitor | E24: 2 | F24: 49.62 | G24: 633 Main St | H24: Online | I24: Pending | J24: TRK75937350 | K24: 2 | L24: SAVE10 | M24: Google | N24: 99.24
A25: ORD200023 | B25: 45756 | C25: C42372 | D25: Phone | E25: 4 | F25: 273.25 | G25: 755 Main St | H25: Debit Card | I25: Cancelled | J25: TRK36168083 | K25: 5 | L25: FREESHIP | M25: Referral | N25: 1093
A26: ORD200024 | B26: 45595 | C26: C17470 | D26: Laptop | E26: 2 | F26: 230.95 | G26: 956 Main St | H26: Online | I26: Delivered | J26: TRK28775057 | K26: 3 | L26: WINTER15 | M26: Referral | N26: 461.9
A27: ORD200025 | B27: 45497 | C27: C42577 | D27: Monitor | E27: 1 | F27: 399.98 | G27: 709 Main St | H27: Debit Card | I27: Delivered | J27: TRK69423327 | K27: 3 | L27: WINTER15 | M27: Email | N27: 399.98
A28: ORD200026 | B28: 45357 | C28: C21944 | D28: Laptop | E28: 5 | F28: 59.55 | G28: 296 Main St | H28: Online | I28: Delivered | J28: TRK80276812 | K28: 6 | M28: Referral | N28: 297.75
A29: ORD200027 | B29: 45344 | C29: C97593 | D29: Printer | E29: 1 | F29: 472.74 | G29: 881 Main St | H29: Online | I29: Shipped | J29: TRK89117573 | K29: 6 | L29: WINTER15 | M29: Google | N29: 472.74
A30: ORD200028 | B30: 45251 | C30: C59823 | D30: Phone | E30: 4 | F30: 160.07 | G30: 568 Main St | H30: Online | I30: Pending | J30: TRK65895539 | K30: 5 | M30: Email | N30: 640.28
A31: ORD200029 | B31: 45555 | C31: C33260 | D31: Desk | E31: 3 | F31: 423.53 | G31: 930 Main St | H31: Credit Card | I31: Delivered | J31: TRK59744090 | K31: 6 | L31: SAVE10 | M31: Referral | N31: 1270.59
A32: ORD200030 | B32: 45738 | C32: C44267 | D32: Monitor | E32: 2 | F32: 426.7 | G32: 895 Main St | H32: Online | I32: Pending | J32: TRK54751444 | K32: 5 | L32: SAVE10 | M32: Referral | N32: 853.4
A33: ORD200031 | B33: 45107 | C33: C26445 | D33: Chair | E33: 3 | F33: 500.08 | G33: 996 Main St | H33: Debit Card | I33: Returned | J33: TRK31229981 | K33: 6 | M33: Facebook | N33: 1500.24
A34: ORD200032 | B34: 45047 | C34: C12388 | D34: Tablet | E34: 5 | F34: 536.72 | G34: 830 Main St | H34: Cash | I34: Delivered | J34: TRK99261395 | K34: 10 | M34: Email | N34: 2683.6
A35: ORD200033 | B35: 45082 | C35: C52184 | D35: Chair | E35: 1 | F35: 162.77 | G35: 912 Main St | H35: Online | I35: Cancelled | J35: TRK73312471 | K35: 4 | L35: WINTER15 | M35: Facebook | N35: 162.77
A36: ORD200034 | B36: 44933 | C36: C67195 | D36: Chair | E36: 4 | F36: 576.52 | G36: 926 Main St | H36: Credit Card | I36: Pending | J36: TRK55467915 | K36: 5 | L36: WINTER15 | M36: Facebook | N36: 2306.08
A37: ORD200035 | B37: 45633 | C37: C50304 | D37: Monitor | E37: 2 | F37: 465.15 | G37: 128 Main St | H37: Online | I37: Shipped | J37: TRK46850888 | K37: 2 | L37: SAVE10 | M37: Facebook | N37: 930.3
A38: ORD200036 | B38: 45785 | C38: C59337 | D38: Laptop | E38: 2 | F38: 534.43 | G38: 465 Main St | H38: Debit Card | I38: Pending | J38: TRK50961250 | K38: 5 | M38: Facebook | N38: 1068.86
A39: ORD200037 | B39: 45579 | C39: C10054 | D39: Laptop | E39: 2 | F39: 76.74 | G39: 409 Main St | H39: Cash | I39: Returned | J39: TRK94005261 | K39: 7 | L39: SAVE10 | M39: Instagram | N39: 153.48
A40: ORD200038 | B40: 45645 | C40: C15924 | D40: Laptop | E40: 1 | F40: 245.89 | G40: 549 Main St | H40: Debit Card | I40: Delivered | J40: TRK14835975 | K40: 3 | L40: SAVE10 | M40: Google | N40: 245.89
...

Sheet Cleaned_Dataset
A1: OrderID | B1: Date | C1: CustomerID | D1: Product | E1: Quantity | F1: UnitPrice | G1: ShippingAddress | H1: PaymentMethod | I1: OrderStatus | J1: TrackingNumber | K1: ItemsInCart | L1: CouponCode | M1: ReferralSource | N1: TotalPrice
A2: ORD200000 | B2: 44930 | C2: C72649 | D2: Monitor | E2: 5 | F2: 570.62 | G2: 928 Main St | H2: Debit Card | I2: Shipped | J2: TRK37947903 | K2: 7 | L2: SAVE10 | M2: Instagram | N2: 2853.1
A3: ORD200001 | B3: 45527 | C3: C75739 | D3: Phone | E3: 2 | F3: 151.35 | G3: 823 Main St | H3: Online | I3: Shipped | J3: TRK91186779 | K3: 3 | L3: SAVE10 | M3: Referral | N3: 302.7
A4: ORD200002 | B4: 45349 | C4: C81728 | D4: Tablet | E4: 5 | F4: 550.68 | G4: 512 Main St | H4: Credit Card | I4: Cancelled | J4: TRK42903982 | K4: 8 | L4: FREESHIP | M4: Email | N4: 2753.4
A5: ORD200003 | B5: 45214 | C5: C33540 | D5: Chair | E5: 1 | F5: 273.19 | G5: 275 Main St | H5: Debit Card | I5: Returned | J5: TRK62788070 | K5: 5 | L5: SAVE10 | M5: Facebook | N5: 273.19
A6: ORD200004 | B6: 45785 | C6: C81840 | D6: Printer | E6: 4 | F6: 626.01 | G6: 668 Main St | H6: Online | I6: Delivered | J6: TRK29241424 | K6: 8 | L6: SAVE10 | M6: Email | N6: 2504.04
A7: ORD200005 | B7: 45222 | C7: C37249 | D7: Phone | E7: 2 | F7: 245.86 | G7: 934 Main St | H7: Credit Card | I7: Shipped | J7: TRK72976927 | K7: 4 | L7: SAVE10 | M7: Instagram | N7: 491.72
A8: ORD200006 | B8: 45825 | C8: C83492 | D8: Laptop | E8: 1 | F8: 664.42 | G8: 986 Main St | H8: Gift Card | I8: Returned | J8: TRK96417362 | K8: 6 | L8: SAVE10 | M8: Facebook | N8: 664.42
A9: ORD200007 | B9: 45058 | C9: C41460 | D9: Monitor | E9: 5 | F9: 149.55 | G9: 706 Main St | H9: Cash | I9: Shipped | J9: TRK78809193 | K9: 9 | L9: FREESHIP | M9: Facebook | N9: 747.75
A10: ORD200008 | B10: 45749 | C10: C26817 | D10: Phone | E10: 2 | F10: 134.28 | G10: 904 Main St | H10: Gift Card | I10: Cancelled | J10: TRK61042692 | K10: 2 | L10: NO_COUPON | M10: Email | N10: 268.56
A11: ORD200009 | B11: 45251 | C11: C31946 | D11: Desk | E11: 4 | F11: 509.38 | G11: 102 Main St | H11: Credit Card | I11: Shipped | J11: TRK33478363 | K11: 6 | L11: SAVE10 | M11: Google | N11: 2037.52
A12: ORD200010 | B12: 45289 | C12: C43443 | D12: Tablet | E12: 5 | F12: 625.97 | G12: 333 Main St | H12: Credit Card | I12: Returned | J12: TRK98859248 | K12: 9 | L12: WINTER15 | M12: Instagram | N12: 3129.85
A13: ORD200011 | B13: 45339 | C13: C93861 | D13: Monitor | E13: 3 | F13: 49.14 | G13: 831 Main St | H13: Online | I13: Returned | J13: TRK48234646 | K13: 7 | L13: SAVE10 | M13: Email | N13: 147.42
... A1201: ORD201199 | B1201: 45088 | C1201: C57502 | D1201: Tablet | E1201: 4 | F1201: 560.58 | G1201: 201 Main St | H1201: Gift Card | I1201: Returned | J1201: TRK51116746 | K1201: 6 | L1201: SAVE10 | M1201: Referral | N1201: 2242.32

Sheet Descriptive Statistics
A1: PHASE 1 - DESCRIPTIVE STATISTICS
A3: Statistic | B3: TotalPrice | C3: UnitPrice | D3: Quantity | E3: ItemsInCart
A4: Count | B4: =COUNT(Table1[TotalPrice]) -> 1200 | C4: =COUNT(Table1[UnitPrice]) -> 1200 | D4: =COUNT(Table1[Quantity]) -> 1200 | E4: =COUNT(Table1[ItemsInCart]) -> 1200
A5: Mean | B5: =AVERAGE(Table1[TotalPrice]) -> 1053.9683 | C5: =AVERAGE(Table1[UnitPrice]) -> 356.41275 | D5: =AVERAGE(Table1[Quantity]) -> 2.9458333 | E5: =AVERAGE(Table1[ItemsInCart]) -> 5.485
A6: Median | B6: =MEDIAN(Table1[TotalPrice]) -> 823.615 | C6: =MEDIAN(Table1[UnitPrice]) -> 364.21 | D6: =MEDIAN(Table1[Quantity]) -> 3 | E6: =MEDIAN(Table1[ItemsInCart]) -> 5
A7: Min | B7: =MIN(Table1[TotalPrice]) -> 11.39 | C7: =MIN(Table1[UnitPrice]) -> 11.39 | D7: =MIN(Table1[Quantity]) -> 1 | E7: =MIN(Table1[ItemsInCart]) -> 1
A8: Max | B8: =MAX(Table1[TotalPrice]) -> 3456.4 | C8: =MAX(Table1[UnitPrice]) -> 699.93 | D8: =MAX(Table1[Quantity]) -> 5 | E8: =MAX(Table1[ItemsInCart]) -> 10
A9: Std Dev | B9: =STDEV(Table1[TotalPrice]) -> 819.85656 | C9: =STDEV(Table1[UnitPrice]) -> 197.17715 | D9: =STDEV(Table1[Quantity]) -> 1.4075571 | E9: =STDEV(Table1[ItemsInCart]) -> 2.2819833
A10: Q1 (25th pct) | B10: =QUARTILE(Table1[TotalPrice],1) -> 410.52 | C10: =QUARTILE(Table1[UnitPrice],1) -> 186.0625 | D10: =QUARTILE(Table1[Quantity],1) -> 2 | E10: =QUARTILE(Table1[ItemsInCart],1) -> 4
A11: Q3 (75th pct) | B11: =QUARTILE(Table1[TotalPrice],3) -> 1578.475 | C11: =QUARTILE(Table1[UnitPrice],3) -> 521.57 | D11: =QUARTILE(Table1[Quantity],3) -> 4 | E11: =QUARTILE(Table1[ItemsInCart],3) -> 7
A12: Mean vs Median gap (TotalPrice) | B12: =B5-B6 -> 230.3533

Sheet By Category
A1: PHASE 2 - CATEGORY BREAKDOWNS
A3: Revenue by Product
A4: Category | B4: Orders | C4: Revenue | D4: Avg Order Value | E4: % of Revenue
A5: Laptop | B5: =COUNTIF(Table1[Product],"Laptop") -> 173 | C5: =SUMIF(Table1[Product],"Laptop",Table1[TotalPrice]) -> 192126.56 | D5: =C5/B5 -> 1110.5582 | E5: =C5/SUM(Table1[TotalPrice]) -> 0.15190729
A6: Phone | B6: =COUNTIF(Table1[Product],"Phone") -> 156 | C6: =SUMIF(Table1[Product],"Phone",Table1[TotalPrice]) -> 151722.39 | D6: =C6/B6 -> 972.57942 | E6: =C6/SUM(Table1[TotalPrice]) -> 0.11996122
A7: Tablet | B7: =COUNTIF(Table1[Product],"Tablet") -> 179 | C7: =SUMIF(Table1[Product],"Tablet",Table1[TotalPrice]) -> 186568.95 | D7: =C7/B7 -> 1042.2846 | E7: =C7/SUM(Table1[TotalPrice]) -> 0.14751309
A8: Monitor | B8: =COUNTIF(Table1[Product],"Monitor") -> 163 | C8: =SUMIF(Table1[Product],"Monitor",Table1[TotalPrice]) -> 175651.41 | D8: =C8/B8 -> 1077.616 | E8: =C8/SUM(Table1[TotalPrice]) -> 0.138881
A9: Printer | B9: =COUNTIF(Table1[Product],"Printer") -> 181 | C9: =SUMIF(Table1[Product],"Printer",Table1[TotalPrice]) -> 195612.61 | D9: =C9/B9 -> 1080.7327 | E9: =C9/SUM(Table1[TotalPrice]) -> 0.15466358
A10: Desk | B10: =COUNTIF(Table1[Product],"Desk") -> 170 | C10: =SUMIF(Table1[Product],"Desk",Table1[TotalPrice]) -> 167459.93 | D10: =C10/B10 -> 985.05841 | E10: =C10/SUM(Table1[TotalPrice]) -> 0.13240431
A11: Chair | B11: =COUNTIF(Table1[Product],"Chair") -> 178 | C11: =SUMIF(Table1[Product],"Chair",Table1[TotalPrice]) -> 195620.11 | D11: =C11/B11 -> 1098.9894 | E11: =C11/SUM(Table1[TotalPrice]) -> 0.15466951
A14: Performance by Referral Source
A15: Category | B15: Orders | C15: Revenue | D15: Avg Order Value | E15: % of Revenue | F15: Cancellation Rate
A16: Email | B16: =COUNTIF(Table1[ReferralSource],"Email") -> 250 | C16: =SUMIF(Table1[ReferralSource],"Email",Table1[TotalPrice]) -> 261808.55 | D16: =C16/B16 -> 1047.2342 | E16: =C16/SUM(Table1[TotalPrice]) -> 0.20700223 | F16: =COUNTIFS(Table1[ReferralSource],"Email",Table1[OrderStatus],"Cancelled")/B16 -> 0.236
A17: Facebook | B17: =COUNTIF(Table1[ReferralSource],"Facebook") -> 228 | C17: =SUMIF(Table1[ReferralSource],"Facebook",Table1[TotalPrice]) -> 250410.9 | D17: =C17/B17 -> 1098.2934 | E17: =C17/SUM(Table1[TotalPrice]) -> 0.19799054 | F17: =COUNTIFS(Table1[ReferralSource],"Facebook",Table1[OrderStatus],"Cancelled")/B17 -> 0.18421053
A18: Google | B18: =COUNTIF(Table1[ReferralSource],"Google") -> 241 | C18: =SUMIF(Table1[ReferralSource],"Google",Table1[TotalPrice]) -> 250441.48 | D18: =C18/B18 -> 1039.1763 | E18: =C18/SUM(Table1[TotalPrice]) -> 0.19801472 | F18: =COUNTIFS(Table1[ReferralSource],"Google",Table1[OrderStatus],"Cancelled")/B18 -> 0.2406639
A19: Instagram | B19: =COUNTIF(Table1[ReferralSource],"Instagram") -> 259 | C19: =SUMIF(Table1[ReferralSource],"Instagram",Table1[TotalPrice]) -> 275285.45 | D19: =C19/B19 -> 1062.8782 | E19: =C19/SUM(Table1[TotalPrice]) -> 0.21765791 | F19: =COUNTIFS(Table1[ReferralSource],"Instagram",Table1[OrderStatus],"Cancelled")/B19 -> 0.15830116
A20: Referral | B20: =COUNTIF(Table1[ReferralSource],"Referral") -> 222 | C20: =SUMIF(Table1[ReferralSource],"Referral",Table1[TotalPrice]) -> 226815.58 | D20: =C20/B20 -> 1021.6918 | E20: =C20/SUM(Table1[TotalPrice]) -> 0.1793346 | F20: =COUNTIFS(Table1[ReferralSource],"Referral",Table1[OrderStatus],"Cancelled")/B20 -> 0.22522523
A23: Spending by Coupon Code
A24: Category | B24: Orders | C24: Revenue | D24: Avg Order Value | E24: % of Revenue
A25: SAVE10 | B25: =COUNTIF(Table1[CouponCode],"SAVE10") -> 286 | C25: =SUMIF(Table1[CouponCode], "SAVE10",Table1[TotalPrice]) -> 304840.02 | D25: =C25/B25 -> 1065.8742 | E25: =C25/SUM(Table1[TotalPrice]) -> 0.24102561
A26: WINTER15 | B26: =COUNTIF(Table1[CouponCode],"WINTER15") -> 292 | C26: =SUMIF(Table1[CouponCode], "WINTER15",Table1[TotalPrice]) -> 302483.54 | D26: =C26/B26 -> 1035.9025 | E26: =C26/SUM(Table1[TotalPrice]) -> 0.23916243
A27: FREESHIP | B27: =COUNTIF(Table1[CouponCode],"FREESHIP") -> 313 | C27: =SUMIF(Table1[CouponCode], "FREESHIP",Table1[TotalPrice]) -> 335036.99 | D27: =C27/B27 -> 1070.4057 | E27: =C27/SUM(Table1[TotalPrice]) -> 0.26490122
A28: NO_COUPON | B28: =COUNTIF(Table1[CouponCode],"NO_COUPON") -> 309 | C28: =SUMIF(Table1[CouponCode], "NO_COUPON",Table1[TotalPrice]) -> 322401.41 | D28: =C28/B28 -> 1043.3703 | E28: =C28/SUM(Table1[TotalPrice]) -> 0.25491074
A31: Orders by Payment Method
A32: Category | B32: Orders | C32: Revenue | D32: Avg Order Value | E32: % of Revenue
A33: Cash | B33: =COUNTIF(Table1[PaymentMethod], "Cash") -> 246 | C33: =SUMIF(Table1[PaymentMethod], "Cash",Table1[TotalPrice]) -> 259786.29 | D33: =C33/B33 -> 1056.0418 | E33: =C33/SUM(Table1[TotalPrice]) -> 0.20540331
A34: Credit Card | B34: =COUNTIF(Table1[PaymentMethod],"Credit Card") -> 234 | C34: =SUMIF(Table1[PaymentMethod], "Credit Card",Table1[TotalPrice]) -> 263847.63 | D34: =C34/B34 -> 1127.554 | E34: =C34/SUM(Table1[TotalPrice]) -> 0.20861446
A35: Debit Card | B35: =COUNTIF(Table1[PaymentMethod], "Debit Card") -> 232 | C35: =SUMIF(Table1[PaymentMethod], "Debit Card",Table1[TotalPrice]) -> 232361.18 | D35: =C35/B35 -> 1001.5568 | E35: =C35/SUM(Table1[TotalPrice]) -> 0.1837193
A36: Gift Card | B36: =COUNTIF(Table1[PaymentMethod], "Gift Card") -> 230 | C36: =SUMIF(Table1[PaymentMethod], "Gift Card",Table1[TotalPrice]) -> 246323.92 | D36: =C36/B36 -> 1070.9736 | E36: =C36/SUM(Table1[TotalPrice]) -> 0.19475911
A37: Online | B37: =COUNTIF(Table1[PaymentMethod], "Online") -> 258 | C37: =SUMIF(Table1[PaymentMethod], "Online",Table1[TotalPrice]) -> 262442.94 | D37: =C37/B37 -> 1017.2207 | E37: =C37/SUM(Table1[TotalPrice]) -> 0.20750382
A40: Order Status Mix
A41: Status | B41: Orders | C41: % of Orders | D41: Gross Value
A42: Delivered | B42: =COUNTIF(Table1[OrderStatus],"Delivered") -> 231 | C42: =B42/1200 -> 0.1925 | D42: =SUMIF(Table1[OrderStatus],"Delivered",Table1[TotalPrice]) -> 242600.32
A43: Shipped | B43: =COUNTIF(Table1[OrderStatus],"Shipped") -> 235 | C43: =B43/1200 -> 0.19583333 | D43: =SUMIF(Table1[OrderStatus],"Shipped",Table1[TotalPrice]) -> 246159.58
A44: Pending | B44: =COUNTIF(Table1[OrderStatus],"Pending") -> 237 | C44: =B44/1200 -> 0.1975 | D44: =SUMIF(Table1[OrderStatus],"Pending",Table1[TotalPrice]) -> 256328.15
A45: Cancelled | B45: =COUNTIF(Table1[OrderStatus],"Cancelled") -> 250 | C45: =B45/1200 -> 0.20833333 | D45: =SUMIF(Table1[OrderStatus],"Cancelled",Table1[TotalPrice]) -> 276396.21
A46: Returned | B46: =COUNTIF(Table1[OrderStatus],"Returned") -> 247 | C46: =B46/1200 -> 0.20583333 | D46: =SUMIF(Table1[OrderStatus],"Returned",Table1[TotalPrice]) -> 243277.7
A48: Realized Revenue (Delivered + Shipped) | D48: =SUM(D42+D43) -> 488759.9
A49: Revenue at Risk (Cancelled + Returned) | D49: =SUM(D45+D46) -> 519673.91
A50: Correlation: ItemsInCart vs Quantity | D50: =CORREL(Table1[ItemsInCart],Table1[Quantity]) -> 0.65006123

Sheet Monthly Trend
A1: PHASE 3 - TRENDS OVER TIME
A3: Month | B3: Orders | C3: Revenue | D3: Avg Order Value
A4: 44927 | B4: =COUNTIFS(Table1[Date],">="&'Monthly Trend'!A4,Table1[Date],"<"&EDATE(A4,1)) -> 47 | C4: =SUMIFS(Table1[TotalPrice],Table1[Date],">="&A4,Table1[Date],"<"&EDATE(A4,1)) -> 56685.75 | D4: =IF(B4=0,0,C4/B4) -> 1206.0798
A5: 44958 | B5: =COUNTIFS(Table1[Date],">="&'Monthly Trend'!A5,Table1[Date],"<"&EDATE(A5,1)) -> 37 | C5: =SUMIFS(Table1[TotalPrice],Table1[Date],">="&A5,Table1[Date],"<"&EDATE(A5,1)) -> 40117.66 | D5: =IF(B5=0,0,C5/B5) -> 1084.2611
A6: 44986 | B6: =COUNTIFS(Table1[Date],">="&'Monthly Trend'!A6,Table1[Date],"<"&EDATE(A6,1)) -> 43 | C6: =SUMIFS(Table1[TotalPrice],Table1[Date],">="&A6,Table1[Date],"<"&EDATE(A6,1)) -> 48609.37 | D6: =IF(B6=0,0,C6/B6) -> 1130.4505
A7: 45017 | B7: =COUNTIFS(Table1[Date],">="&'Monthly Trend'!A7,Table1[Date],"<"&EDATE(A7,1)) -> 31 | C7: =SUMIFS(Table1[TotalPrice],Table1[Date],">="&A7,Table1[Date],"<"&EDATE(A7,1)) -> 27751.71 | D7: =IF(B7=0,0,C7/B7) -> 895.21645
A8: 45047 | B8: =COUNTIFS(Table1[Date],">="&'Monthly Trend'!A8,Table1[Date],"<"&EDATE(A8,1)) -> 49 | C8: =SUMIFS(Table1[TotalPrice],Table1[Date],">="&A8,Table1[Date],"<"&EDATE(A8,1)) -> 63836.84 | D8: =IF(B8=0,0,C8/B8) -> 1302.7927
A9: 45078 | B9: =COUNTIFS(Table1[Date],">="&'Monthly Trend'!A9,Table1[Date],"<"&EDATE(A9,1)) -> 45 | C9: =SUMIFS(Table1[TotalPrice],Table1[Date],">="&A9,Table1[Date],"<"&EDATE(A9,1)) -> 49500.19 | D9: =IF(B9=0,0,C9/B9) -> 1100.0042
A10: 45108 | B10: =COUNTIFS(Table1[Date],">="&'Monthly Trend'!A10,Table1[Date],"<"&EDATE(A10,1)) -> 44 | C10: =SUMIFS(Table1[TotalPrice],Table1[Date],">="&A10,Table1[Date],"<"&EDATE(A10,1)) -> 42820.66 | D10: =IF(B10=0,0,C10/B10) -> 973.19682
A11: 45139 | B11: =COUNTIFS(Table1[Date],">="&'Monthly Trend'!A11,Table1[Date],"<"&EDATE(A11,1)) -> 51 | C11: =SUMIFS(Table1[TotalPrice],Table1[Date],">="&A11,Table1[Date],"<"&EDATE(A11,1)) -> 54352.14 | D11: =IF(B11=0,0,C11/B11) -> 1065.7282
A12: 45170 | B12: =COUNTIFS(Table1[Date],">="&'Monthly Trend'!A12,Table1[Date],"<"&EDATE(A12,1)) -> 29 | C12: =SUMIFS(Table1[TotalPrice],Table1[Date],">="&A12,Table1[Date],"<"&EDATE(A12,1)) -> 29526.67 | D12: =IF(B12=0,0,C12/B12) -> 1018.161
A13: 45200 | B13: =COUNTIFS(Table1[Date],">="&'Monthly Trend'!A13,Table1[Date],"<"&EDATE(A13,1)) -> 47 | C13: =SUMIFS(Table1[TotalPrice],Table1[Date],">="&A13,Table1[Date],"<"&EDATE(A13,1)) -> 52607.85 | D13: =IF(B13=0,0,C13/B13) -> 1119.316
A14: 45231 | B14: =COUNTIFS(Table1[Date],">="&'Monthly Trend'!A14,Table1[Date],"<"&EDATE(A14,1)) -> 41 | C14: =SUMIFS(Table1[TotalPrice],Table1[Date],">="&A14,Table1[Date],"<"&EDATE(A14,1)) -> 43079.67 | D14: =IF(B14=0,0,C14/B14) -> 1050.7237
A15: 45261 | B15: =COUNTIFS(Table1[Date],">="&'Monthly Trend'!A15,Table1[Date],"<"&EDATE(A15,1)) -> 46 | C15: =SUMIFS(Table1[TotalPrice],Table1[Date],">="&A15,Table1[Date],"<"&EDATE(A15,1)) -> 43754.73 | D15: =IF(B15=0,0,C15/B15) -> 951.18978
... A33: 45809 | B33: =COUNTIFS(Table1[Date],">="&'Monthly Trend'!A33,Table1[Date],"<"&EDATE(A33,1)) -> 49 | C33: =SUMIFS(Table1[TotalPrice],Table1[Date],">="&A33,Table1[Date],"<"&EDATE(A33,1)) -> 53047.4 | D33: =IF(B33=0,0,C33/B33) -> 1082.6

Sheet Outliers
A1: PHASE 4 - OUTLIER ANALYSIS (IQR METHOD, TotalPrice)
A3: Q1 | B3: =QUARTILE(Table1[TotalPrice],1) -> 410.52
A4: Q3 | B4: =QUARTILE(Table1[TotalPrice],3) -> 1578.475
A5: IQR | B5: =B4-B3 -> 1167.955
A6: Lower bound (Q1-1.5*IQR) | B6: =B3-1.5*B5 -> -1341.4125
A7: Upper bound (Q3+1.5*IQR) | B7: =B4+1.5*B5 -> 3330.4075
A8: Orders below lower bound | B8: =COUNTIF([1]Data!N2:N1201,"<"&B6) -> #VALUE!
A9: Orders above upper bound | B9: =COUNTIF([1]Data!N2:N1201,">"&B7) -> #VALUE!
A11: Top 10 largest orders (inspect these individually):
A12: Rank | B12: OrderID | C12: TotalPrice
A13: 1 | B13: =INDEX(Table1[OrderID],MATCH(C13,Table1[TotalPrice],0)) -> ORD200789 | C13: =LARGE(Table1[TotalPrice],1) -> 3456.4
A14: 2 | B14: =INDEX(Table1[OrderID],MATCH(C14,Table1[TotalPrice],0)) -> ORD201122 | C14: =LARGE(Table1[TotalPrice],2) -> 3390.95
A15: 3 | B15: =INDEX(Table1[OrderID],MATCH(C15,Table1[TotalPrice],0)) -> ORD200632 | C15: =LARGE(Table1[TotalPrice],3) -> 3390.8
A16: 4 | B16: =INDEX(Table1[OrderID],MATCH(C16,Table1[TotalPrice],0)) -> ORD200469 | C16: =LARGE(Table1[TotalPrice],4) -> 3384.9
A17: 5 | B17: =INDEX(Table1[OrderID],MATCH(C17,Table1[TotalPrice],0)) -> ORD200328 | C17: =LARGE(Table1[TotalPrice],5) -> 3370.2
A18: 6 | B18: =INDEX(Table1[OrderID],MATCH(C18,Table1[TotalPrice],0)) -> ORD200107 | C18: =LARGE(Table1[TotalPrice],6) -> 3353.75
A19: 7 | B19: =INDEX(Table1[OrderID],MATCH(C19,Table1[TotalPrice],0)) -> ORD200326 | C19: =LARGE(Table1[TotalPrice],7) -> 3352.4
A20: 8 | B20: =INDEX(Table1[OrderID],MATCH(C20,Table1[TotalPrice],0)) -> ORD201065 | C20: =LARGE(Table1[TotalPrice],8) -> 3334
A21: 9 | B21: =INDEX(Table1[OrderID],MATCH(C21,Table1[TotalPrice],0)) -> ORD201031 | C21: =LARGE(Table1[TotalPrice],9) -> 3322.55
A22: 10 | B22: =INDEX(Table1[OrderID],MATCH(C22,Table1[TotalPrice],0)) -> ORD200463 | C22: =LARGE(Table1[TotalPrice],10) -> 3313.9

Sheet Key Observations
A1: PHASE 5 - KEY OBSERVATIONS (fill in after reviewing the numbers)
A3: # | B3: Theme | C3: Question to answer | D3: Your observation (1-2 sentences) | E3: Business implication
A4: 1 | B4: Revenue scale & average order | C4: What is total revenue, and what does a typical (median) order look like vs the mean? | D4: Total gross order value is approximately £1.26M across 1,200 orders. The mean order value (1,053.97) is 28% higher than the median (823.62), indicating a right-skewed distribution where a minority of large orders inflate the average. | E4: The median is the more reliable figure for forecasting typical customer behaviour; using the mean would overstate expected revenue per order.
A5: 2 | B5: Best & worst products | C5: Which product drives the most revenue? Which the least? Is revenue concentrated? | D5: Chair is top (£195,620), Printer nearly tied (£195,613); Phone is lowest (£151,722). All 7 products sit between 12–15.5% of revenue → revenue is evenly spread, not concentrated. | E5: no single product dependency, but also no star product.
A6: 3 | B6: Trend over time | C6: Is monthly revenue growing, declining, or flat across 2023-2025? Any seasonal spikes? | D6: Monthly revenue fluctuates around ~£42K/month with no sustained growth or decline across Jan 2023–Jun 2025 | E6: business is stagnant; growth must come from fixing cancellations or channel investment.
A7: 4 | B7: Order fulfilment risk | C7: What % of orders are Cancelled or Returned, and how much revenue does that put at risk? | D7: 41.4% of all orders are Cancelled (250) or Returned (247), representing £519,674 in gross value — more than the £488,760 actually realized through Delivered and Shipped orders. | E7: The business loses more order value than it captures; reducing cancellations is a bigger revenue lever than acquiring new orders.
A8: 5 | B8: Referral source quality | C8: Which channel brings the most valuable orders? Which has the highest cancellation rate? | D8: nstagram = most orders (259) AND lowest cancellation rate (15.8%); Google = highest cancellation rate (24.1%); Email close behind (23.6%). | E8: shift spend toward Instagram-like channels; investigate why Google/Email orders fall through.
A9: 6 | B9: Coupon behaviour | C9: Do coupon users spend more or less per order than NO_COUPON customers? | D9: Avg order value is nearly identical across all groups; SAVE10 (1,065.87), WINTER15 (1,035.90), FREESHIP (1,070.41), NO_COUPON (1,043.37). | E9: coupons aren't increasing basket size, so they're margin giveaways unless they drive acquisition/retention.
A10: 7 | B10: Outliers | C10: Any orders outside the IQR bounds? If none, state that the data has no extreme anomalies. | D10: 8 orders exceed the IQR upper bound (3,330.41), max 3,456.40; 0 below. All are legitimate max-quantity × high-price combinations, not data errors. | E10: no anomalies to remove; the 8 represent a small high-value segment worth studying.
A11: 8 | B11: Correlation | C11: Does ItemsInCart relate to Quantity purchased (CORREL result)? What does that imply? | D11: CORREL = 0.65 between ItemsInCart and Quantity, a moderate positive relationship | E11: larger carts convert into larger purchases, so cart-building features (bundles, "frequently bought together") likely lift order size.
